Workbook

Sheet FINAL v3
B3: Datos del sensor al aire | H3: Datos del sensor exhalación
B4: WET | C4: AET | D4: WEe | E4: AEe | F4: WE0 | G4: AE0 | H4: WEu | I4: kH | J4: Weu' | K4: AEu | L4: Temp | M4: K'T | N4: KT | O4: WEC (algoritmo 3) | P4: WEC (algoritmo 2) | Q4: Sensibilidad ISB | R4: PPB(algoritmo 3) | S4: PPB(algoritmo 2)
A5: prueba 1* | B5: 327.6 | C5: 318.6 | D5: 265.1425 | E5: 273.475 | F5: =+B5-D5 -> 62.4575 | G5: =+C5-E5 -> 45.125 | H5: 321.4 | I5: 1.0461038 | J5: =H5*I5 -> 336.21777 | K5: 324.5 | L5: 37 | M5: 1.1 | N5: 0.9 | O5: =(J5-D5)-(F5-G5)-(M5*(K5-E5)) -> -2.3847288 | P5: =(J5-D5)-(N5*(F5/G5)*(K5-E5)) -> 7.5139516 | Q5: 432 | R5: =+O5/Q5*1000 -> -5.5202056 | S5: =+P5/Q5*1000 -> 17.393407
B6: 327.6 | C6: 318.6 | D6: 265.1425 | E6: 273.475 | F6: =+B6-D6 -> 62.4575 | G6: =+C6-E6 -> 45.125 | H6: 326.6 | I6: 1.0461038 | J6: =H6*I6 -> 341.65751 | K6: 316.8 | L6: 37 | M6: 1.1 | N6: 0.9 | O6: =(J6-D6)-(F6-G6)-(M6*(K6-E6)) -> 11.525011 | P6: =(J6-D6)-(N6*(F6/G6)*(K6-E6)) -> 22.545503 | Q6: 432 | R6: =+O6/Q6*1000 -> 26.678266 | S6: =+P6/Q6*1000 -> 52.188664
B7: 370 | C7: 331.6 | D7: 265.1425 | E7: 273.475 | F7: =+B7-D7 -> 104.8575 | G7: =+C7-E7 -> 58.125 | H7: 322.6 | I7: 1.0461038 | J7: =H7*I7 -> 337.4731 | K7: 336 | L7: 37 | M7: 1.1 | N7: 0.9 | O7: =(J7-D7)-(F7-G7)-(M7*(K7-E7)) -> -43.179404 | P7: =(J7-D7)-(N7*(F7/G7)*(K7-E7)) -> -29.184994 | Q7: 432 | R7: =+O7/Q7*1000 -> -99.952325 | S7: =+P7/Q7*1000 -> -67.557857
A8: * mediciones de 45 seg
A11: WEu = uncorrected raw WE output
A12: AEu = uncorrected raw AE output
A13: WEc = corrected WE output
A14: WEe = WE electronic offset on the AFE or ISB
A15: AEe = AE electronic offset on the AFE or ISB
A16: WEo = WE sensor zero, i.e. the sensor WE output in zero air
A17: AEo = AE sensor zero, i.e. the sensor AE output in zero air
A18: WET = Total WE zero offset
A19: AET = Total AE zero offset
A21: Algoritmo 2
A25: Algoritmo 3

Sheet FINAL v2
B7: Datos del sensor al aire | H7: Datos del sensor exhalación
B8: WET | C8: AET | D8: WEe | E8: AEe | F8: WE0 | G8: AE0 | H8: WEu | I8: kH | J8: Weu' | K8: AEu | L8: T | M8: K'T | N8: KT | O8: WEC (algoritmo 3) | P8: WEC (algoritmo 2) | Q8: Sensibilidad ISB | R8: PPB(algoritmo 3) | S8: PPB(algoritmo 2)
A9: prueba 1* | B9: 314.8 | C9: 309.9 | D9: 265.1425 | E9: 273.475 | F9: =+B9-D9 -> 49.6575 | G9: =+C9-E9 -> 36.425 | H9: 308.5 | I9: 1.0461038 | J9: =H9*I9 -> 322.72303 | K9: 313.5 | L9: 37 | M9: 1.1 | N9: 0.9 | O9: =(J9-D9)-(F9-G9)-(M9*(K9-E9)) -> 0.32053175 | P9: =(J9-D9)-(N9*(F9/G9)*(K9-E9)) -> 8.4717522 | Q9: 432 | R9: =+O9/Q9*1000 -> 0.74197165 | S9: =+P9/Q9*1000 -> 19.610538
A10: prueba 2* | B10: 314.8 | C10: 309.9 | D10: 265.1425 | E10: 273.475 | F10: =+B10-D10 -> 49.6575 | G10: =+C10-E10 -> 36.425 | H10: 309.5 | I10: 1.0461038 | J10: =H10*I10 -> 323.76914 | K10: 311.5 | L10: 37 | M10: 1.1 | N10: 0.9 | O10: =(J10-D10)-(F10-G10)-(M10*(K10-E10)) -> 3.5666356 | P10: =(J10-D10)-(N10*(F10/G10)*(K10-E10)) -> 11.971761 | Q10: 432 | R10: =+O10/Q10*1000 -> 8.2561009 | S10: =+P10/Q10*1000 -> 27.712411
A11: * mediciones de 45 seg | H11: 120 | K11: 293
A14: WEu = uncorrected raw WE output
A15: AEu = uncorrected raw AE output
A16: WEc = corrected WE output
A17: WEe = WE electronic offset on the AFE or ISB
A18: AEe = AE electronic offset on the AFE or ISB
A19: WEo = WE sensor zero, i.e. the sensor WE output in zero air
A20: AEo = AE sensor zero, i.e. the sensor AE output in zero air
A21: WET = Total WE zero offset
A22: AET = Total AE zero offset
A24: Algoritmo 2
A28: Algoritmo 3

Sheet Algoritmos Factores
D1: T / °C
B2: Algorithm | C2: Factor | D2: -30 | E2: -20 | F2: -10 | G2: 0 | H2: 10 | I2: 20 | J2: 30 | K2: 40 | L2: 50
A3: NO-B4 | B3: 1 | C3: nT | D3: 2.9 | E3: 2.9 | F3: 2.2 | G3: 1.8 | H3: 1.7 | I3: 1.6 | J3: 1.5 | K3: 1.4 | L3: 1.3
B4: 2 | C4: kT | D4: 1.8 | E4: 1.8 | F4: 1.4 | G4: 1.1 | H4: 1.1 | I4: 1 | J4: 0.9 | K4: 0.9 | L4: 0.8
B5: 3 | C5: k'T | D5: 0.8 | E5: 0.8 | F5: 0.8 | G5: 0.8 | H5: 0.9 | I5: 1 | J5: 1.1 | K5: 1.2 | L5: 1.3
B6: 4 | C6: k''T | D6: -25 | E6: -25 | F6: -25 | G6: -25 | H6: -16 | I6: 0 | J6: 56 | K6: 200 | L6: 615

Sheet GENERAL
R5: 0,43 mv/ppb
C6: Correciòn por Temperatura
C7: WET | D7: AET | E7: WEe | F7: AEe | G7: WE0 | H7: AE0 | I7: WEu | J7: kH | K7: Weu' | L7: AEu | M7: T | N7: K'T | O7: KT | P7: WEC (algoritmo 3) | Q7: WEC (algoritmo 2) | R7: Sensibilidad ISB | S7: PPB(algoritmo 3) | T7: PPB(algoritmo 2) | V7: Correcciòn Humedad
A8: 1 | B8: Sin Flujo de Aire | C8: =+'WET sin flujo'!U23*1000 -> 325.975 | D8: =+'WET sin flujo'!U46*1000 -> 312.8725 | E8: =+'WEe sin flujo'!U23*1000 -> 265.1425 | F8: =+'WEe sin flujo'!U46*1000 -> 273.475 | G8: =+C8-E8 -> 60.8325 | H8: =+D8-F8 -> 39.3975 | L8: 322 | N8: 1.1 | O8: 0.9 | P8: =(K8-E8)-(G8-H8)-(N8*(L8-F8)) -> -339.955 | Q8: =(K8-E8)-(O8*(G8/H8)*(L8-F8)) -> -332.5759 | R8: 432 | S8: =+P8/R8*1000 -> -786.93287 | T8: =+Q8/R8*1000 -> -769.85162 | V8: WEu | W8: kH | X8: Weu'
B9: Con Flujo de Aire | C9: =0.34675*1000 -> 346.75 | D9: =0.313125*1000 -> 313.125 | E9: =+E8 -> 265.1425 | F9: =+F8 -> 273.475 | G9: =+C9-E9 -> 81.6075 | H9: =+D9-F9 -> 39.65 | L9: =+L8 -> 322 | N9: 1.1 | O9: 0.9 | P9: =(K9-E9)-(G9-H9)-(N9*(L9-F9)) -> -360.4775 | Q9: =(K9-E9)-(O9*(G9/H9)*(L9-F9)) -> -355.0291 | R9: =+R8 -> 432 | S9: =+P9/R9*1000 -> -834.43866 | T9: =+Q9/R9*1000 -> -821.82661 | V9: 261 | W9: =+WET_4!AA288 | X9: =+W9*V9 -> #VALUE!
A10: 2 | B10: Sin Flujo de Aire | C10: =WET_2!X76 -> 319.93618 | D10: =+WET_2!X36 -> 306.34145 | E10: =+E8 -> 265.1425 | F10: =+F8 -> 273.475 | G10: =+C10-E10 -> 54.793684 | H10: =+D10-F10 -> 32.866447 | L10: =+L8 -> 322 | N10: 1.1 | O10: 0.9 | P10: =(K10-E10)-(G10-H10)-(N10*(L10-F10)) -> -340.44724 | Q10: =(K10-E10)-(O10*(G10/H10)*(L10-F10)) -> -337.95162 | R10: 432 | S10: =+P10/R10*1000 -> -788.07231 | T10: =+Q10/R10*1000 -> -782.29542
B11: Con Flujo de Aire | C11: =WET_2!X157 -> 334.16875 | D11: =WET_2!X117 -> 305.89309 | E11: =+E8 -> 265.1425 | F11: =+F8 -> 273.475 | G11: =+C11-E11 -> 69.02625 | H11: =+D11-F11 -> 32.418092 | L11: =+L10 -> 322 | N11: 1.1 | O11: 0.9 | P11: =(K11-E11)-(G11-H11)-(N11*(L11-F11)) -> -355.12816 | Q11: =(K11-E11)-(O11*(G11/H11)*(L11-F11)) -> -358.13221 | R11: 432 | S11: =+P11/R11*1000 -> -822.05592 | T11: =+Q11/R11*1000 -> -829.00974 | V11: WEu = uncorrected raw WE output
A12: 3 | B12: Sin Flujo de Aire | C12: =+WET_3!X68 -> 306.08992 | D12: =+WET_3!X32 -> 298.07944 | E12: =+E10 -> 265.1425 | F12: =+F10 -> 273.475 | G12: =+C12-E12 -> 40.947419 | H12: =+D12-F12 -> 24.604435 | L12: =+L10 -> 322 | N12: 1.1 | O12: 0.9 | P12: =(K12-E12)-(G12-H12)-(N12*(L12-F12)) -> -334.86298 | Q12: =(K12-E12)-(O12*(G12/H12)*(L12-F12)) -> -337.82355 | R12: 432 | S12: =+P12/R12*1000 -> -775.1458 | T12: =+Q12/R12*1000 -> -781.99896 | V12: AEu = uncorrected raw AE output
B13: Con Flujo de Aire | C13: =+WET_3!X141 -> 316.44718 | D13: =+WET_3!X105 -> 297.2879 | E13: =+E10 -> 265.1425 | F13: =+F10 -> 273.475 | G13: =+C13-E13 -> 51.304677 | H13: =+D13-F13 -> 23.812903 | L13: =+L12 -> 322 | N13: 1.1 | O13: 0.9 | P13: =(K13-E13)-(G13-H13)-(N13*(L13-F13)) -> -346.01177 | Q13: =(K13-E13)-(O13*(G13/H13)*(L13-F13)) -> -359.23449 | R13: 432 | S13: =+P13/R13*1000 -> -800.95318 | T13: =+Q13/R13*1000 -> -831.56133 | V13: WEc = corrected WE output
A14: 4 | B14: Sin Flujo de Aire | C14: =+WET_4!Y116 -> 314.86727 | D14: =+WET_4!Y56 -> 303.4638 | E14: =+E12 -> 265.1425 | F14: =+F12 -> 273.475 | G14: =+C14-E14 -> 49.724773 | H14: =+D14-F14 -> 29.988796 | L14: =+L12 -> 322 | N14: 1 | O14: 1 | P14: =(K14-E14)-(G14-H14)-(N14*(L14-F14)) -> -333.40348 | Q14: =(K14-E14)-(O14*(G14/H14)*(L14-F14)) -> -345.60237 | R14: 432 | S14: =+P14/R14*1000 -> -771.76731 | T14: =+Q14/R14*1000 -> -800.00548 | V14: WEe = WE electronic offset on the AFE or ISB
B15: Con Flujo de Aire | C15: =+WET_4!Y237 -> 320.81484 | D15: =+WET_4!Y176 -> 302.90451 | E15: =+E12 -> 265.1425 | F15: =+F12 -> 273.475 | G15: =+C15-E15 -> 55.672344 | H15: =+D15-F15 -> 29.429514 | L15: =+L14 -> 322 | N15: 1 | O15: 1 | P15: =(K15-E15)-(G15-H15)-(N15*(L15-F15)) -> -339.91033 | Q15: =(K15-E15)-(O15*(G15/H15)*(L15-F15)) -> -356.93812 | R15: 432 | S15: =+P15/R15*1000 -> -786.82947 | T15: =+Q15/R15*1000 -> -826.24565 | V15: AEe = AE electronic offset on the AFE or ISB
B16: Sin Flujo de Aire | C16: =+WET_4!Y118 -> 0 | D16: =+WET_4!Y58 -> 0 | E16: =+E14 -> 265.1425 | F16: =+F14 -> 273.475 | G16: =+C16-E16 -> -265.1425 | H16: =+D16-F16 -> -273.475 | L16: =+L14 -> 322 | N16: 1 | O16: 1 | P16: =(K16-E16)-(G16-H16)-(N16*(L16-F16)) -> -322 | Q16: =(K16-E16)-(O16*(G16/H16)*(L16-F16)) -> -312.18899 | R16: 432 | S16: =+P16/R16*1000 -> -745.37037 | T16: =+Q16/R16*1000 -> -722.65971 | V16: WEo = WE sensor zero, i.e. the sensor WE output in zero air
B17: Con Flujo de Aire | C17: =+WET_4!Y239 -> 0 | D17: =+WET_4!Y178 -> 0 | E17: =+E14 -> 265.1425 | F17: =+F14 -> 273.475 | G17: =+C17-E17 -> -265.1425 | H17: =+D17-F17 -> -273.475 | L17: =+L16 -> 322 | N17: 1 | O17: 1 | P17: =(K17-E17)-(G17-H17)-(N17*(L17-F17)) -> -322 | Q17: =(K17-E17)-(O17*(G17/H17)*(L17-F17)) -> -312.18899 | R17: 432 | S17: =+P17/R17*1000 -> -745.37037 | T17: =+Q17/R17*1000 -> -722.65971 | V17: AEo = AE sensor zero, i.e. the sensor AE output in zero air
A18: 5 | B18: Sin Flujo de Aire | C18: 337.6 | D18: 320 | E18: =+E14 -> 265.1425 | F18: =+F14 -> 273.475 | G18: =+C18-E18 -> 72.4575 | H18: =+D18-F18 -> 46.525 | L18: =+L14 -> 322 | N18: 1 | O18: 1 | P18: =(K18-E18)-(G18-H18)-(N18*(L18-F18)) -> -339.6 | Q18: =(K18-E18)-(O18*(G18/H18)*(L18-F18)) -> -340.71478 | R18: 432 | S18: =+P18/R18*1000 -> -786.11111 | T18: =+Q18/R18*1000 -> -788.69161 | V18: WET = Total WE zero offset
B19: Con Flujo de Aire y H100% | C19: 271.6 | D19: 322 | E19: =+E14 -> 265.1425 | F19: =+F14 -> 273.475 | G19: =+C19-E19 -> 6.4575 | H19: =+D19-F19 -> 48.525 | L19: =+L18 -> 322 | N19: 1 | O19: 1 | P19: =(K19-E19)-(G19-H19)-(N19*(L19-F19)) -> -271.6 | Q19: =(K19-E19)-(O19*(G19/H19)*(L19-F19)) -> -271.6 | R19: 432 | S19: =+P19/R19*1000 -> -628.7037 | T19: =+Q19/R19*1000 -> -628.7037 | V19: AET = Total AE zero offset
A20: 5 | B20: Sin Flujo de Aire | C20: 337.6 | D20: 320 | E20: =+E16 -> 265.1425 | F20: =+F16 -> 273.475 | G20: =+C20-E20 -> 72.4575 | H20: =+D20-F20 -> 46.525 | L20: =+L16 -> 322 | N20: 1.1 | O20: 0.9 | P20: =(K20-E20)-(G20-H20)-(N20*(L20-F20)) -> -344.4525 | Q20: =(K20-E20)-(O20*(G20/H20)*(L20-F20)) -> -333.15755 | R20: 432 | S20: =+P20/R20*1000 -> -797.34375 | T20: =+Q20/R20*1000 -> -771.19803
B21: Con Flujo de Aire y H100% | C21: =+C19*W9 -> #VALUE! | D21: 322 | E21: =+E16 -> 265.1425 | F21: =+F16 -> 273.475 | G21: =+C21-E21 -> #VALUE! | H21: =+D21-F21 -> 48.525 | L21: =+L20 -> 322 | N21: 1.1 | O21: 0.9 | P21: =(K21-E21)-(G21-H21)-(N21*(L21-F21)) -> #VALUE! | Q21: =(K21-E21)-(O21*(G21/H21)*(L21-F21)) -> #VALUE! | R21: 432 | S21: =+P21/R21*1000 -> #VALUE! | T21: =+Q21/R21*1000 -> #VALUE! | V21: Algoritmo 2
A22: 6 | C22: =+WET_4!Y286 -> 315.20625 | D22: =+WET_4!Y287 -> 305.8625 | E22: =+E18 -> 265.1425 | F22: =+F18 -> 273.475 | G22: =+C22-E22 -> 50.06375 | H22: =+D22-F22 -> 32.3875 | I22: 274 | J22: =+W9 | K22: =I22*J22 -> #VALUE! | L22: 306.95 | M22: 37 | N22: 1.15 | O22: 0.9 | P22: =(K22-E22)-(G22-H22)-(N22*(L22-F22)) -> #VALUE! | Q22: =(K22-E22)-(O22*(G22/H22)*(L22-F22)) -> #VALUE! | R22: 432 | S22: =+P22/R22*1000 -> #VALUE! | T22: =+Q22/R22*1000 -> #VALUE!
C23: =+C22 -> 315.20625 | D23: 305.9 | E23: =+E18 -> 265.1425 | F23: =+F18 -> 273.475 | G23: =+C23-E23 -> 50.06375 | H23: =+D23-F23 -> 32.425 | I23: 261 | J23: 1.1479003 | K23: =I23*J23 -> 299.60198 | L23: 305.64 | M23: 37 | N23: 1.1 | O23: 0.9 | P23: =(K23-E23)-(G23-H23)-(N23*(L23-F23)) -> -18.56077 | Q23: =(K23-E23)-(O23*(G23/H23)*(L23-F23)) -> -10.236602 | R23: 432 | S23: =+P23/R23*1000 -> -42.964745 | T23: =+Q23/R23*1000 -> -23.695838
A24: 7 | C24: =+WET_4!Y291 -> 312.575 | D24: =+WET_4!Y292 -> 303.525 | E24: =+E20 -> 265.1425 | F24: =+F20 -> 273.475 | G24: =+C24-E24 -> 47.4325 | H24: =+D24-F24 -> 30.05 | I24: 274 | J24: 1.1977201 | K24: =I24*J24 -> 328.1753 | L24: 306.95 | M24: 37 | N24: 1.1 | O24: 0.9 | P24: =(K24-E24)-(G24-H24)-(N24*(L24-F24)) -> 8.8278041 | Q24: =(K24-E24)-(O24*(G24/H24)*(L24-F24)) -> 15.477974 | R24: 432 | S24: =+P24/R24*1000 -> 20.434732 | T24: =+Q24/R24*1000 -> 35.828644
C25: =+C24 -> 312.575 | D25: =+D24 -> 303.525 | E25: =+E20 -> 265.1425 | F25: =+F20 -> 273.475 | G25: =+C25-E25 -> 47.4325 | H25: =+D25-F25 -> 30.05 | I25: 261 | J25: 1.1977201 | K25: =I25*J25 -> 312.60494 | L25: 305.64 | M25: 37 | N25: 1.1 | O25: 0.9 | P25: =(K25-E25)-(G25-H25)-(N25*(L25-F25)) -> -5.301557 | Q25: =(K25-E25)-(O25*(G25/H25)*(L25-F25)) -> 1.7686085 | R25: 432 | S25: =+P25/R25*1000 -> -12.272123 | T25: =+Q25/R25*1000 -> 4.0940012 | V25: Algoritmo 3
A26: 8 | C26: =+WET_4!Y251 -> 337.56875 | D26: =+WET_4!Y252 -> 320.03125 | E26: =+E22 -> 265.1425 | F26: =+F22 -> 273.475 | G26: =+C26-E26 -> 72.42625 | H26: =+D26-F26 -> 46.55625 | I26: 274 | J26: =+WET_4!AA253 -> 1.2428608 | K26: =I26*J26 -> 340.54385 | L26: 306.95 | M26: 37 | N26: 1.1 | O26: 0.9 | P26: =(K26-E26)-(G26-H26)-(N26*(L26-F26)) -> 12.708848 | Q26: =(K26-E26)-(O26*(G26/H26)*(L26-F26)) -> 28.532843 | R26: 432 | S26: =+P26/R26*1000 -> 29.418629 | T26: =+Q26/R26*1000 -> 66.048247
C27: =+C26 -> 337.56875 | D27: =+D26 -> 320.03125 | E27: =+E22 -> 265.1425 | F27: =+F22 -> 273.475 | G27: =+C27-E27 -> 72.42625 | H27: =+D27-F27 -> 46.55625 | I27: 261 | J27: =+J26 -> 1.2428608 | K27: =I27*J27 -> 324.38666 | L27: 305.64 | M27: 37 | N27: 1.1 | O27: 0.9 | P27: =(K27-E27)-(G27-H27)-(N27*(L27-F27)) -> -2.0073419 | Q27: =(K27-E27)-(O27*(G27/H27)*(L27-F27)) -> 14.20979 | R27: 432 | S27: =+P27/R27*1000 -> -4.6466248 | T27: =+Q27/R27*1000 -> 32.893032
A29: 9 | B29: prueba 1 | C29: =+WET_ensayo!Z11 -> 324.29219 | D29: =+WET_ensayo!Z12 -> 312.09844 | E29: =+E25 -> 265.1425 | F29: =+F25 -> 273.475 | G29: =+C29-E29 -> 59.149688 | H29: =+D29-F29 -> 38.623437 | I29: 272 | J29: =+WET_ensayo!Z47 -> 1.2265791 | K29: =I29*J29 -> 333.62952 | L29: 316.1 | M29: 37 | N29: 1.1 | O29: 0.9 | P29: =(K29-E29)-(G29-H29)-(N29*(L29-F29)) -> 1.0732711 | Q29: =(K29-E29)-(O29*(G29/H29)*(L29-F29)) -> 9.7369451 | R29: 432 | S29: =+P29/R29*1000 -> 2.4844238 | T29: =+Q29/R29*1000 -> 22.539225
B30: prueba 2 | C30: =+C29 -> 324.29219 | D30: =+D29 -> 312.09844 | E30: =+E25 -> 265.1425 | F30: =+F25 -> 273.475 | G30: =+C30-E30 -> 59.149688 | H30: =+D30-F30 -> 38.623437 | I30: 265 | J30: =+J29 -> 1.2265791 | K30: =I30*J30 -> 325.04347 | L30: 315.7 | M30: 37 | N30: 1.1 | O30: 0.9 | P30: =(K30-E30)-(G30-H30)-(N30*(L30-F30)) -> -7.0727828 | Q30: =(K30-E30)-(O30*(G30/H30)*(L30-F30)) -> 1.7022116 | R30: 432 | S30: =+P30/R30*1000 -> -16.372182 | T30: =+Q30/R30*1000 -> 3.9403047
B31: mediodnes de 45 seg
A32: 10 | B32: prueba 1 | C32: 314.8 | D32: 309.9 | E32: 265.1425 | F32: 273.475 | G32: =+C32-E32 -> 49.6575 | H32: =+D32-F32 -> 36.425 | I32: 308.5 | J32: 1.0461038 | K32: =I32*J32 -> 322.72303 | L32: 313.5 | M32: 37 | N32: 1.1 | O32: 0.9 | P32: =(K32-E32)-(G32-H32)-(N32*(L32-F32)) -> 0.32053175 | Q32: =(K32-E32)-(O32*(G32/H32)*(L32-F32)) -> 8.4717522 | R32: 432 | S32: =+P32/R32*1000 -> 0.74197165 | T32: =+Q32/R32*1000 -> 19.610538
B33: prueba 2 | C33: 314.8 | D33: 309.9 | E33: 265.1425 | F33: 273.475 | G33: =+C33-E33 -> 49.6575 | H33: =+D33-F33 -> 36.425 | I33: 309.5 | J33: 1.0461038 | K33: =I33*J33 -> 323.76914 | L33: 311.5 | M33: 37 | N33: 1.1 | O33: 0.9 | P33: =(K33-E33)-(G33-H33)-(N33*(L33-F33)) -> 3.5666356 | Q33: =(K33-E33)-(O33*(G33/H33)*(L33-F33)) -> 11.971761 | R33: 432 | S33: =+P33/R33*1000 -> 8.2561009 | T33: =+Q33/R33*1000 -> 27.712411
AB253: =+Z251/Z253 -> #DIV/0!
AB260: =+Z258/Z260 -> #DIV/0!
AB278: =+Z276/Z278 -> #DIV/0!
AB288: =+Z286/Z288 -> #DIV/0!
AB293: =+Z291/Z293 -> #DIV/0!

Sheet WET_ensayo
A2: ENSAYO - temp 25°C - humedad ambiente 64%
A3: 120 | B3: 0 | C3: WE | D3: 324.75 | E3: 325 | F3: 324.375 | G3: 324.875 | H3: 324.375 | I3: 327 | J3: 326.25 | K3: 326.125 | L3: 323.5 | M3: 324.625 | N3: 322.5 | O3: 323.25 | P3: 325.25 | Q3: 323.25 | R3: 324.5 | S3: 324.875 | T3: 323.375 | U3: 324.875 | V3: 327.875 | W3: 326.625 | X3: =AVERAGE(D3:W3) -> 324.8625
A4: 120 | B4: 0 | C4: AE | D4: 315.125 | E4: 312.125 | F4: 311.375 | G4: 312.625 | H4: 312.75 | I4: 312.875 | J4: 313 | K4: 312.5 | L4: 314.25 | M4: 313 | N4: 311.625 | O4: 310.875 | P4: 312.375 | Q4: 311.375 | R4: 310.875 | S4: 311.875 | T4: 314.625 | U4: 311.25 | V4: 313.125 | W4: 313.75 | X4: =AVERAGE(D4:W4) -> 312.56875
A5: 120 | B5: 1 | C5: WE | D5: 354.625 | E5: 354.625 | F5: 354.875 | G5: 356.25 | H5: 355.375 | I5: 354.875 | J5: 355.5 | K5: 354.625 | L5: 353.75 | M5: 351.75 | N5: 354.875 | O5: 353.75 | P5: 352.25 | Q5: 352.375 | R5: 350.375 | S5: 350.875 | T5: 351.625 | U5: 353.375 | V5: 350 | W5: 352 | X5: =AVERAGE(D5:W5) -> 353.3875
A6: 120 | B6: 1 | C6: AE | D6: 308.375 | E6: 310 | F6: 310 | G6: 309.625 | H6: 310.75 | I6: 309.875 | J6: 312.75 | K6: 312 | L6: 311.375 | M6: 309.75 | N6: 311.75 | O6: 311 | P6: 310.5 | Q6: 310.75 | R6: 310.625 | S6: 310 | T6: 311.5 | U6: 311.25 | V6: 310.25 | W6: 312 | X6: =AVERAGE(D6:W6) -> 310.70625
A8: 130 | B8: 0 | C8: WE | D8: 324.25 | E8: 322.75 | F8: 325.125 | G8: 323.125 | H8: 324.125 | I8: 323.25 | J8: 323 | K8: 323 | L8: 322.375 | M8: 323.25 | N8: 322.625 | O8: 323.25 | P8: 321.125 | Q8: 323.5 | R8: 323.125 | S8: 324.5 | T8: 327.875 | U8: 324.625 | V8: 323.875 | W8: 325.125 | X8: =AVERAGE(D8:W8) -> 323.69375
A9: 130 | B9: 0 | C9: AE | D9: 311.875 | E9: 312 | F9: 311.875 | G9: 311.75 | H9: 312.625 | I9: 311.625 | J9: 311.375 | K9: 313 | L9: 310.875 | M9: 309.125 | N9: 310.75 | O9: 310.75 | P9: 311.125 | Q9: 310.125 | R9: 312.375 | S9: 312.375 | T9: 315.5 | U9: 314 | V9: 313 | W9: 312 | X9: =AVERAGE(D9:W9) -> 311.90625
A10: 130 | B10: 1 | C10: WE | D10: 356.75 | E10: 354.75 | F10: 354 | G10: 354.25 | H10: 354 | I10: 353.5 | J10: 351.125 | K10: 350.875 | L10: 352.75 | M10: 352.875 | N10: 351.625 | O10: 353.125 | P10: 351.875 | Q10: 352.875 | R10: 351.875 | S10: 352.625 | T10: 350.125 | U10: 349.75 | V10: 348.125 | W10: 350.875 | X10: =AVERAGE(D10:W10) -> 352.3875
A11: 130 | B11: 1 | C11: AE | D11: 309.875 | E11: 309.375 | F11: 307.75 | G11: 308.75 | H11: 310 | I11: 310.5 | J11: 307.75 | K11: 310.375 | L11: 311.375 | M11: 309.625 | N11: 309 | O11: 309.75 | P11: 311 | Q11: 310.375 | R11: 309.25 | S11: 311.375 | T11: 309.25 | U11: 309.75 | V11: 308.375 | W11: 309.75 | X11: =AVERAGE(D11:W11) -> 309.6625 | Z11: =AVERAGE(X3,X8,X13,X18) -> 324.29219
Z12: =AVERAGE(X4,X9,X14,X19) -> 312.09844
A13: 140 | B13: 0 | C13: WE | D13: 325.875 | E13: 325 | F13: 324.75 | G13: 321.75 | H13: 322.5 | I13: 323.25 | J13: 322.25 | K13: 322.625 | L13: 322.125 | M13: 324 | N13: 324.5 | O13: 324.125 | P13: 325.125 | Q13: 326.75 | R13: 325.875 | S13: 325.875 | T13: 325.375 | U13: 325 | V13: 324 | W13: 323.125 | X13: =AVERAGE(D13:W13) -> 324.19375 | Z13: =AVERAGE(X5,X10,X15,X20) -> 353.69687
A14: 140 | B14: 0 | C14: AE | D14: 313.375 | E14: 312.75 | F14: 311.75 | G14: 311.125 | H14: 311 | I14: 310.5 | J14: 312.125 | K14: 310.75 | L14: 309.125 | M14: 310 | N14: 311.625 | O14: 312.875 | P14: 314 | Q14: 313.125 | R14: 313.875 | S14: 310.75 | T14: 312.25 | U14: 312.25 | V14: 310.875 | W14: 313.375 | X14: =AVERAGE(D14:W14) -> 311.875 | Z14: =AVERAGE(X6,X11,X16,X21) -> 310.39688
A15: 140 | B15: 1 | C15: WE | D15: 358.75 | E15: 358.25 | F15: 354.75 | G15: 356.125 | H15: 353.75 | I15: 356.125 | J15: 353.25 | K15: 354.625 | L15: 352.5 | M15: 351.75 | N15: 355.375 | O15: 353.125 | P15: 352 | Q15: 352.5 | R15: 352 | S15: 353.375 | T15: 352.375 | U15: 352.25 | V15: 352.375 | W15: 351.875 | X15: =AVERAGE(D15:W15) -> 353.85625
A16: 140 | B16: 1 | C16: AE | D16: 309.75 | E16: 308.625 | F16: 311.375 | G16: 310.25 | H16: 309.125 | I16: 310 | J16: 309.5 | K16: 310.875 | L16: 311.25 | M16: 310 | N16: 312.25 | O16: 311.375 | P16: 310.125 | Q16: 311.125 | R16: 310.5 | S16: 310.375 | T16: 309.5 | U16: 310.625 | V16: 310.625 | W16: 311.75 | X16: =AVERAGE(D16:W16) -> 310.45
A18: 150 | B18: 0 | C18: WE | D18: 326.25 | E18: 325.75 | F18: 325 | G18: 322.875 | H18: 324.5 | I18: 323.5 | J18: 323.5 | K18: 324.75 | L18: 324 | M18: 322.375 | N18: 322.625 | O18: 323.875 | P18: 324.375 | Q18: 323.5 | R18: 323.125 | S18: 325.5 | T18: 325.25 | U18: 326.625 | V18: 325.75 | W18: 325.25 | X18: =AVERAGE(D18:W18) -> 324.41875
A19: 150 | B19: 0 | C19: AE | D19: 315.125 | E19: 309.875 | F19: 312.375 | G19: 311.25 | H19: 311.5 | I19: 312 | J19: 312 | K19: 311 | L19: 311.875 | M19: 312.25 | N19: 311.75 | O19: 312.25 | P19: 310.125 | Q19: 311.125 | R19: 310.875 | S19: 313.25 | T19: 313.875 | U19: 314.25 | V19: 312.25 | W19: 311.875 | X19: =AVERAGE(D19:W19) -> 312.04375
A20: 150 | B20: 1 | C20: WE | D20: 358.125 | E20: 355.5 | F20: 359 | G20: 357.375 | H20: 357.125 | I20: 356.5 | J20: 356.375 | K20: 352.25 | L20: 352.75 | M20: 352.625 | N20: 352.5 | O20: 355.25 | P20: 354 | Q20: 352.75 | R20: 354.375 | S20: 354.25 | T20: 357.75 | U20: 353.125 | V20: 357 | W20: 354.5 | X20: =AVERAGE(D20:W20) -> 355.15625
A21: 150 | B21: 1 | C21: AE | D21: 309 | E21: 310.375 | F21: 310.5 | G21: 312.5 | H21: 312.125 | I21: 310.875 | J21: 311.125 | K21: 309.375 | L21: 310.625 | M21: 310.25 | N21: 311.5 | O21: 311.375 | P21: 311.75 | Q21: 309.25 | R21: 310.625 | S21: 309.625 | T21: 312.5 | U21: 309.375 | V21: 312.375 | W21: 310.25 | X21: =AVERAGE(D21:W21) -> 310.76875
A25: ENSAYO - temp 25°C - humedad absotuta estimada 100% (nebulizador)
A26: 160 | B26: 0 | C26: WE | D26: 323.625 | E26: 323.375 | F26: 320.625 | G26: 324.375 | H26: 323.25 | I26: 326.375 | J26: 325.125 | K26: 321.625 | L26: 322.75 | M26: 325 | N26: 322.5 | O26: 323.5 | P26: 322.125 | Q26: 322.75 | R26: 321.75 | S26: 324.625 | T26: 324.5 | U26: 325.125 | V26: 322.875 | W26: 322.875 | X26: =AVERAGE(D26:W26) -> 323.4375
A27: 160 | B27: 0 | C27: AE | D27: 311.125 | E27: 310.25 | F27: 310.875 | G27: 312.125 | H27: 313.875 | I27: 312.625 | J27: 312.875 | K27: 310.625 | L27: 308 | M27: 311.625 | N27: 310.625 | O27: 312.125 | P27: 311.375 | Q27: 309.625 | R27: 311.875 | S27: 314 | T27: 312.5 | U27: 312.625 | V27: 311.625 | W27: 310.125 | X27: =AVERAGE(D27:W27) -> 311.525
A28: 160 | B28: 1 | C28: WE | D28: 146.75 | E28: 149 | F28: 154.875 | G28: 159.625 | H28: 164 | I28: 165.625 | J28: 169 | K28: 172.875 | L28: 172.75 | M28: 173.875 | N28: 179.375 | O28: 184.875 | P28: 184.125 | Q28: 186 | R28: 189.5 | S28: 191.75 | T28: 197 | U28: 200.625 | V28: 200.25 | W28: 202.5 | X28: =AVERAGE(D28:W28) -> 177.21875
A29: 160 | B29: 1 | C29: AE | D29: 312 | E29: 311.5 | F29: 312.875 | G29: 312.625 | H29: 313.625 | I29: 313.75 | J29: 314.25 | K29: 314.25 | L29: 312.75 | M29: 312 | N29: 312.875 | O29: 313.625 | P29: 311.125 | Q29: 312.875 | R29: 311.875 | S29: 314.375 | T29: 313.375 | U29: 315.625 | V29: 314.625 | W29: 314.5 | X29: =AVERAGE(D29:W29) -> 313.225
A30: mucha condensación
A31: 15 min de ventilación por condensación de humedad
A33: 180 | B33: 0 | C33: WE | D33: 328.375 | E33: 328.375 | F33: 325.125 | G33: 325.75 | H33: 326.75 | I33: 326.5 | J33: 327.125 | K33: 324.375 | L33: 325 | M33: 327 | N33: 328.625 | O33: 328.25 | P33: 327.625 | Q33: 328.5 | R33: 327.625 | S33: 328.75 | T33: 330.375 | U33: 330.375 | V33: 330 | W33: 331 | X33: =AVERAGE(D33:W33) -> 327.775
A34: 180 | B34: 0 | C34: AE | D34: 313.5 | E34: 314 | F34: 310.75 | G34: 310.875 | H34: 310.625 | I34: 313 | J34: 314.125 | K34: 311.25 | L34: 312.625 | M34: 313.25 | N34: 313.75 | O34: 313.75 | P34: 314.25 | Q34: 315 | R34: 313.75 | S34: 313.25 | T34: 316.25 | U34: 316.5 | V34: 314.625 | W34: 315 | X34: =AVERAGE(D34:W34) -> 313.50625
A35: 180 | B35: 1 | C35: WE | D35: 359.25 | E35: 361.25 | F35: 359.875 | G35: 360 | H35: 359.875 | I35: 360 | J35: 358.5 | K35: 359.625 | L35: 359.625 | M35: 357.625 | N35: 356.75 | O35: 356.125 | P35: 355.5 | Q35: 357.25 | R35: 354.5 | S35: 354.875 | T35: 354.75 | U35: 353.75 | V35: 354.125 | W35: 354.875 | X35: =AVERAGE(D35:W35) -> 357.40625
A36: 180 | B36: 1 | C36: AE | D36: 311.75 | E36: 311.625 | F36: 312.875 | G36: 312 | H36: 312 | I36: 312.75 | J36: 311.5 | K36: 313.25 | L36: 313.25 | M36: 312 | N36: 312 | O36: 311.25 | P36: 311.75 | Q36: 311 | R36: 310.5 | S36: 311.375 | T36: 310.75 | U36: 310.875 | V36: 311.125 | W36: 311.25 | X36: =AVERAGE(D36:W36) -> 311.74375
A38: 190 | B38: 0 | C38: WE | D38: 329 | E38: 326.25 | F38: 325.375 | G38: 326.75 | H38: 328.5 | I38: 325.625 | J38: 325.875 | K38: 324 | L38: 324.125 | M38: 326.375 | N38: 326.375 | O38: 329.5 | P38: 326.625 | Q38: 326.375 | R38: 326.75 | S38: 327.75 | T38: 327.125 | U38: 326.375 | V38: 326.875 | W38: 325.75 | X38: =AVERAGE(D38:W38) -> 326.56875
A39: 190 | B39: 0 | C39: AE | D39: 314.875 | E39: 314.625 | F39: 312.75 | G39: 311.125 | H39: 314.75 | I39: 313.375 | J39: 311.625 | K39: 311.625 | L39: 310.5 | M39: 313.25 | N39: 312.25 | O39: 315.125 | P39: 314 | Q39: 312 | R39: 313.75 | S39: 312.875 | T39: 315.375 | U39: 312.875 | V39: 313.625 | W39: 312.875 | X39: =AVERAGE(D39:W39) -> 313.1625
A40: 190 | B40: 1 | C40: WE | D40: 177.125 | E40: 183 | F40: 188 | G40: 190.5 | H40: 197.125 | I40: 199.125 | J40: 196.625 | K40: 198.25 | L40: 201.875 | M40: 202 | N40: 210.875 | O40: 211 | P40: 212.125 | Q40: 215 | R40: 220.5 | S40: 223 | T40: 224 | U40: 224.375 | V40: 226.625 | W40: 227.125 | X40: =AVERAGE(D40:W40) -> 206.4125
A41: 190 | B41: 1 | C41: AE | D41: 316.125 | E41: 316.25 | F41: 318.625 | G41: 318.875 | H41: 319 | I41: 317.5 | J41: 315.25 | K41: 314.625 | L41: 316 | M41: 313.375 | N41: 317 | O41: 315.375 | P41: 314 | Q41: 314.875 | R41: 317.5 | S41: 316.625 | T41: 316.5 | U41: 316.75 | V41: 314.75 | W41: 315.125 | X41: =AVERAGE(D41:W41) -> 316.20625
A43: 2 min ventilación entre mediciones
A45: 200 | B45: 0 | C45: WE | D45: 332.875 | E45: 332.25 | F45: 348.25 | G45: 330.125 | H45: 325.625 | I45: 326.75 | J45: 328.25 | K45: 327.375 | L45: 329.875 | M45: 331.75 | N45: 329 | O45: 329 | P45: 329.5 | Q45: 330.875 | R45: 331.625 | S45: 330.125 | T45: 328.25 | U45: 332.25 | V45: 330.75 | W45: 331.625 | X45: =AVERAGE(D45:W45) -> 330.80625
A46: 200 | B46: 0 | C46: AE | D46: 314.375 | E46: 316.125 | F46: 335.875 | G46: 310.875 | H46: 308.5 | I46: 310.125 | J46: 308.25 | K46: 311 | L46: 314 | M46: 314.75 | N46: 311.5 | O46: 311.5 | P46: 312 | Q46: 313 | R46: 313 | S46: 315.625 | T46: 311 | U46: 312.375 | V46: 312.75 | W46: 314.125 | X46: =AVERAGE(D46:W46) -> 313.5375
A47: 200 | B47: 1 | C47: WE | D47: 248.25 | E47: 252.125 | F47: 251.5 | G47: 261.75 | H47: 261.625 | I47: 263.25 | J47: 260.75 | K47: 260.625 | L47: 262.125 | M47: 266.625 | N47: 265.125 | O47: 272.25 | P47: 268.5 | Q47: 265.75 | R47: 266.625 | S47: 269.25 | T47: 268.75 | U47: 276.625 | V47: 273.875 | W47: 272.375 | X47: =AVERAGE(D47:W47) -> 264.3875 | Z47: =+Z11/X47 -> 1.2265791 | AA47: =+Z11/310 -> 1.0461038
A48: 200 | B48: 1 | C48: AE | D48: 312.5 | E48: 314 | F48: 311.5 | G48: 318.875 | H48: 318.875 | I48: 316.875 | J48: 313.375 | K48: 314.75 | L48: 313.125 | M48: 315.375 | N48: 317.75 | O48: 319.875 | P48: 316.875 | Q48: 314.25 | R48: 314.25 | S48: 314.75 | T48: 314.75 | U48: 321.125 | V48: 318.125 | W48: 315.375 | X48: =AVERAGE(F48:W48) -> 316.10417
A50: 15 min de ventilación por condensación de humedad
A52: ENSAYO - temp 25°C - humedad absotuta estimada 100% (exhalación)
...

Sheet WET_4
A1: 700 | B1: 0 | C1: AE | D1: 303.875 | E1: 305.5 | F1: 305 | G1: 304.375 | H1: 304.625 | I1: 306.875 | J1: 306.5 | L1: 304.625 | M1: 306.875 | N1: 305.5 | O1: 305.25 | P1: 307.25 | Q1: 305.75 | R1: 305 | S1: 303.375 | T1: 304.125 | U1: 305.25 | V1: 303.625 | W1: 306.875 | X1: 306.625 | Y1: =AVERAGE(D1:X1) -> 305.34375
A2: 720 | B2: 0 | C2: AE | D2: 303.125 | E2: 305.25 | F2: 302.125 | G2: 304.875 | H2: 307.5 | I2: 306.5 | J2: 305.75 | L2: 305.375 | M2: 303.125 | N2: 304.875 | O2: 304.375 | P2: 303.625 | Q2: 304.75 | R2: 305.5 | S2: 305.75 | T2: 303.5 | U2: 303.75 | V2: 304.375 | W2: 304.125 | X2: 303 | Y2: =AVERAGE(D2:X2) -> 304.5625
A3: 740 | B3: 0 | C3: AE | D3: 304.5 | E3: 303.125 | F3: 299.375 | G3: 302.875 | H3: 304.25 | I3: 306.125 | J3: 304.875 | L3: 301.75 | M3: 302.75 | N3: 303.75 | O3: 306 | P3: 304.125 | Q3: 304 | R3: 305.375 | S3: 301.875 | T3: 301.125 | U3: 304.375 | V3: 304.625 | W3: 303.375 | X3: 305.625 | Y3: =AVERAGE(D3:X3) -> 303.69375
A4: 760 | B4: 0 | C4: AE | D4: 305.125 | E4: 304.5 | F4: 304.875 | G4: 305.25 | H4: 304.25 | I4: 301.25 | J4: 304.875 | L4: 304 | M4: 303 | N4: 304.5 | O4: 307 | P4: 304.75 | Q4: 305.5 | R4: 305.125 | S4: 303.875 | T4: 304 | U4: 307 | V4: 300.5 | W4: 303.25 | X4: 301.75 | Y4: =AVERAGE(D4:X4) -> 304.21875
A5: 780 | B5: 0 | C5: AE | D5: 303.625 | E5: 303.5 | F5: 304.125 | G5: 303.375 | H5: 302.375 | I5: 303.25 | J5: 304.5 | L5: 305.125 | M5: 305.25 | N5: 305.75 | O5: 303 | P5: 302.875 | Q5: 304 | R5: 305 | S5: 304.5 | T5: 305 | U5: 304.25 | V5: 303.375 | W5: 303.125 | X5: 300.875 | Y5: =AVERAGE(D5:X5) -> 303.84375
A6: 800 | B6: 0 | C6: AE | D6: 303.5 | E6: 306.625 | F6: 304.25 | G6: 304.875 | H6: 303.5 | I6: 303.125 | J6: 304 | L6: 303.125 | M6: 301.75 | N6: 301 | O6: 303 | P6: 302.625 | Q6: 305 | R6: 303.125 | S6: 303 | T6: 303.875 | U6: 303.5 | V6: 305.25 | W6: 304.5 | X6: 305.625 | Y6: =AVERAGE(D6:X6) -> 303.7625
A7: 820 | B7: 0 | C7: AE | D7: 305 | E7: 305.625 | F7: 304 | G7: 307 | H7: 301.5 | I7: 303.875 | J7: 302.375 | K7: 303 | L7: 300.875 | M7: 301.875 | N7: 304 | O7: 303.625 | P7: 303 | Q7: 301.875 | R7: 304.125 | S7: 302.5 | T7: 302.5 | U7: 303.75 | V7: 304.5 | W7: 303.5 | X7: 302.5 | Y7: =AVERAGE(D7:X7) -> 303.38095
A8: 840 | B8: 0 | C8: AE | D8: 303.875 | E8: 303.75 | F8: 302 | G8: 307.375 | H8: 302.5 | I8: 303.125 | J8: 304.75 | L8: 305 | M8: 302.5 | N8: 302 | O8: 302.5 | P8: 304.625 | Q8: 304.5 | R8: 302.625 | S8: 302.875 | T8: 301.25 | U8: 302.5 | V8: 303 | W8: 302 | X8: 302.625 | Y8: =AVERAGE(D8:X8) -> 303.26875
A9: 860 | B9: 0 | C9: AE | D9: 303.875 | E9: 302.5 | F9: 302.875 | G9: 303 | H9: 303.625 | I9: 304.125 | J9: 302.375 | L9: 303.75 | M9: 303 | N9: 303.375 | O9: 301.75 | P9: 302.875 | Q9: 302.75 | R9: 304.25 | S9: 303.125 | T9: 303.375 | U9: 301.875 | V9: =+WET_4!AA288 | W9: 303.375 | X9: 303.375 | Y9: =AVERAGE(D9:X9) -> 303.11842
A10: 880 | B10: 0 | C10: AE | D10: 306.25 | E10: 302.875 | F10: 303.25 | G10: 303.375 | H10: 302.625 | I10: 302.875 | J10: 302.75 | L10: 301.125 | M10: 305.375 | N10: 302.75 | O10: 303.75 | P10: 304.25 | Q10: 304.75 | R10: 303.5 | S10: 302.125 | T10: 301.125 | U10: 304.5 | V10: 303.25 | W10: 302.125 | X10: 303.75 | Y10: =AVERAGE(D10:X10) -> 303.31875
A11: 900 | B11: 0 | C11: AE | D11: 304.625 | E11: 303.875 | F11: 304.875 | G11: 304.125 | H11: 303 | I11: 302.375 | J11: 303.25 | L11: 302.125 | M11: 305.75 | N11: 303.75 | O11: 305.125 | P11: 304.75 | Q11: 298.875 | R11: 306.75 | S11: 300.5 | T11: 305 | U11: 303.875 | V11: 303.375 | W11: 302.875 | X11: 302.75 | Y11: =AVERAGE(D11:X11) -> 303.58125
A12: 920 | B12: 0 | C12: AE | D12: 302.125 | E12: 303.125 | F12: 302.5 | G12: 303.375 | H12: 303.25 | I12: 304.875 | J12: 302.5 | L12: 303.125 | M12: 304.5 | N12: 304.375 | O12: 302.375 | P12: 303.375 | Q12: 302.625 | R12: 302.5 | S12: 302.375 | T12: 302.625 | U12: 302.5 | V12: 304 | W12: 302.5 | X12: 301.75 | Y12: =AVERAGE(D12:X12) -> 303.01875
A13: 940 | B13: 0 | C13: AE | D13: 304.125 | E13: 306.625 | F13: 303.75 | G13: 305.875 | H13: 302.5 | I13: 303.5 | J13: 302.875 | L13: 303.875 | M13: 300 | N13: 303.5 | O13: 302 | P13: 301.875 | Q13: 302.625 | R13: 303.25 | S13: 302.375 | T13: 303.125 | U13: 301.25 | V13: 305.25 | W13: 305 | X13: 305.125 | Y13: =AVERAGE(D13:X13) -> 303.425
A14: 960 | B14: 0 | C14: AE | D14: 303.875 | E14: 303.625 | F14: 302.625 | G14: 303.375 | H14: 304.375 | I14: 304 | J14: 303.75 | L14: 302.125 | M14: 302.375 | N14: 301.5 | O14: 302.25 | P14: 303.5 | Q14: 302.25 | R14: 304.125 | S14: 303.625 | T14: 302.75 | U14: 302.25 | V14: 303.25 | W14: 302.875 | X14: 302.125 | Y14: =AVERAGE(D14:X14) -> 303.03125
A15: 980 | B15: 0 | C15: AE | D15: 302.625 | E15: 303.375 | F15: 303.875 | G15: 301.25 | H15: 301.25 | I15: 302 | J15: 305.75 | L15: 305.25 | M15: 302.25 | N15: 302.25 | O15: 302.75 | P15: 304.875 | Q15: 303.375 | R15: 303.75 | S15: 303.625 | T15: 302.75 | U15: 304.125 | V15: 302.375 | W15: 303.125 | X15: 302.75 | Y15: =AVERAGE(D15:X15) -> 303.16875
A16: 1000 | B16: 0 | C16: AE | D16: 301.875 | E16: 303.625 | F16: 303.125 | G16: 303.125 | H16: 302.25 | I16: 302 | J16: 302.25 | L16: 303.625 | M16: 303 | N16: 304.5 | O16: 303.75 | P16: 302.875 | Q16: 303.375 | R16: 303.625 | S16: 305.375 | T16: 302.875 | U16: 303.375 | V16: 302.5 | W16: 301.875 | X16: 301.875 | Y16: =AVERAGE(D16:X16) -> 303.04375
A17: 1020 | B17: 0 | C17: AE | D17: 302.625 | E17: 302.25 | F17: 305.625 | G17: 302.375 | H17: 304.625 | I17: 305.5 | J17: 303.125 | L17: 303.75 | M17: 303.625 | N17: 303.25 | O17: 302.25 | P17: 303.625 | Q17: 302.5 | R17: 304.625 | S17: 303.625 | T17: 302.75 | U17: 302.75 | V17: 303 | W17: 303.25 | X17: 304 | Y17: =AVERAGE(D17:X17) -> 303.45625
A18: 1040 | B18: 0 | C18: AE | D18: 304.375 | E18: 302.875 | F18: 303.375 | G18: 302.875 | H18: 302.5 | I18: 302.125 | J18: 304.625 | L18: 303.25 | M18: 303 | N18: 304.375 | O18: 304.75 | P18: 305 | Q18: 304.25 | R18: 305.5 | S18: 303.75 | T18: 306.25 | U18: 304.625 | V18: 303.875 | W18: 304.5 | X18: 301 | Y18: =AVERAGE(D18:X18) -> 303.84375
A19: 1060 | B19: 0 | C19: AE | D19: 302.625 | E19: 304.5 | F19: 303.375 | G19: 303 | H19: 303.25 | I19: 302.375 | J19: 302.75 | L19: 304 | M19: 303 | N19: 303.125 | O19: 305.125 | P19: 304 | Q19: 302.625 | R19: 302.875 | S19: 302.5 | T19: 304.375 | U19: 302.625 | V19: 301.75 | W19: 302.875 | X19: 302.5 | Y19: =AVERAGE(D19:X19) -> 303.1625
A20: 1080 | B20: 0 | C20: AE | D20: 304.25 | E20: 303.25 | F20: 304.875 | G20: 306.25 | H20: 302.625 | I20: 303.25 | J20: 303.875 | L20: 302.25 | M20: 302.875 | N20: 301.75 | O20: 301.625 | P20: 303.875 | Q20: 302 | R20: 301.75 | S20: 302.125 | T20: 301.375 | U20: 302.375 | V20: 305 | W20: 303.125 | X20: 305.375 | Y20: =AVERAGE(D20:X20) -> 303.19375
A21: 1100 | B21: 0 | C21: AE | D21: 303 | E21: 305.375 | F21: 302.125 | G21: 300.75 | H21: 303.125 | I21: 302.5 | J21: 303 | L21: 300.875 | M21: 304.5 | N21: 303.25 | O21: 301.125 | P21: 304.625 | Q21: 303 | R21: 301.875 | S21: 305.375 | T21: 305.25 | U21: 303.5 | V21: 304 | W21: 303.125 | X21: 304.625 | Y21: =AVERAGE(D21:X21) -> 303.25
A22: 1120 | B22: 0 | C22: AE | D22: 302.5 | E22: 303.75 | F22: 303.625 | G22: 304.625 | H22: 302.25 | I22: 306.125 | J22: 303.75 | K22: =+V9 | L22: 302 | M22: 303.625 | N22: 302 | O22: 302.25 | P22: 304.25 | Q22: 302.375 | R22: 303.125 | S22: 303.75 | T22: 303.125 | U22: 303.125 | V22: 301.625 | W22: 303.125 | X22: 304.875 | Y22: =AVERAGE(D22:X22) -> 303.29375
A23: 1140 | B23: 0 | C23: AE | D23: 303.5 | E23: 303.875 | F23: 303.875 | G23: 304.125 | H23: 303.375 | I23: 303.75 | J23: 304.875 | K23: 1.1479003 | L23: 302.875 | M23: 303.75 | N23: 303.125 | O23: 302.5 | P23: 302.375 | Q23: 304.625 | R23: 300.625 | S23: 302.5 | T23: 304.125 | U23: 303.125 | V23: 302.625 | W23: 302.75 | X23: 304.625 | Y23: =AVERAGE(D23:X23) -> 288.95942
A24: 1160 | B24: 0 | C24: AE | D24: 302.875 | E24: 304.375 | F24: 305.25 | G24: 301.5 | H24: 302.5 | I24: 303.125 | J24: 302.875 | L24: 302.875 | M24: 302.75 | N24: 302.5 | O24: 303.625 | P24: 304 | Q24: 302.875 | R24: 302.5 | S24: 305.125 | T24: 304.25 | U24: 303.125 | V24: 303.5 | W24: 304.875 | X24: 303 | Y24: =AVERAGE(D24:X24) -> 303.375
A25: 1180 | B25: 0 | C25: AE | D25: 303 | E25: 301.5 | F25: 303.875 | G25: 304.125 | H25: 303.75 | I25: 304.75 | J25: 303.25 | L25: 303.125 | M25: 303.375 | N25: 302.375 | O25: 301.875 | P25: 304.5 | Q25: 303.75 | R25: 304.125 | S25: 302.375 | T25: 302.625 | U25: 303 | V25: 304.875 | W25: 303.125 | X25: 306 | Y25: =AVERAGE(D25:X25) -> 303.46875
A26: 1200 | B26: 0 | C26: AE | D26: 303.75 | E26: 303.25 | F26: 301.5 | G26: 302.375 | H26: 304.5 | I26: 301.25 | J26: 302.875 | L26: 302.625 | M26: 304.375 | N26: 304 | O26: 303.125 | P26: 303 | Q26: 303.25 | R26: 302.5 | S26: 304.5 | T26: 302.375 | U26: 300.5 | V26: 303.125 | W26: 300.75 | X26: 306.25 | Y26: =AVERAGE(D26:X26) -> 302.99375
A27: 1220 | B27: 0 | C27: AE | D27: 302 | E27: 302.125 | F27: 303.5 | G27: 301.875 | H27: 302.75 | I27: 302.625 | J27: 301.625 | L27: 302.25 | M27: 302.75 | N27: 303.75 | O27: 301.875 | P27: 302.75 | Q27: 304.875 | R27: 304.25 | S27: 302.75 | T27: 303.75 | U27: 302.875 | V27: 304 | W27: 302 | X27: 301.625 | Y27: =AVERAGE(D27:X27) -> 302.8
A28: 1240 | B28: 0 | C28: AE | D28: 302.625 | E28: 305 | F28: 303.25 | G28: 303.625 | H28: 303.5 | I28: 304.375 | J28: 301.5 | L28: 303.5 | M28: 302.5 | N28: 303.375 | O28: 302.875 | P28: 303.125 | Q28: 305.25 | R28: 302.5 | S28: 303.625 | T28: 303.125 | U28: 302.375 | V28: 301.75 | W28: 302.625 | X28: 301.25 | Y28: =AVERAGE(D28:X28) -> 303.0875
A29: 1260 | B29: 0 | C29: AE | D29: 302.75 | E29: 302.5 | F29: 304.375 | G29: 302.625 | H29: 301.625 | I29: 301.875 | J29: 302.25 | L29: 300.25 | M29: 301.375 | N29: 301.625 | O29: 302.125 | P29: 302.25 | Q29: 303.125 | R29: 302.25 | S29: 302.125 | T29: 303.375 | U29: 303.625 | V29: 302.125 | W29: 303.5 | X29: 303.375 | Y29: =AVERAGE(D29:X29) -> 302.45625
A30: 1280 | B30: 0 | C30: AE | D30: 301 | E30: 303.5 | F30: 302.75 | G30: 300.25 | H30: 301.875 | I30: 302.75 | J30: 303.25 | L30: 301.625 | M30: 304.25 | N30: 301.625 | O30: 304 | P30: 302.75 | Q30: 302.625 | R30: 303.5 | S30: 301.25 | T30: 302.75 | U30: 303.125 | V30: 300.5 | W30: 301.5 | X30: 302.75 | Y30: =AVERAGE(D30:X30) -> 302.38125
A31: 1300 | B31: 0 | C31: AE | D31: 301.75 | E31: 303.75 | F31: 303.625 | G31: 304 | H31: 302.375 | I31: 302.375 | J31: 300 | L31: 302.125 | M31: 301.875 | N31: 301.75 | O31: 300.625 | P31: 303.875 | Q31: 302.125 | R31: 302.125 | S31: 302.875 | T31: 302.75 | U31: 302.25 | V31: 303 | W31: 304.625 | X31: 302.25 | Y31: =AVERAGE(D31:X31) -> 302.50625
A32: 1320 | B32: 0 | C32: AE | D32: 301.875 | E32: 303 | F32: 301.5 | G32: 300.875 | H32: 302.25 | I32: 300.625 | J32: 301.625 | L32: 301.125 | M32: 301.75 | N32: 300.875 | O32: 301.875 | P32: 303.5 | Q32: 300.625 | R32: 304.25 | S32: 302.625 | T32: 305.625 | U32: 302.25 | V32: 303.125 | W32: 302.75 | X32: 302.625 | Y32: =AVERAGE(D32:X32) -> 302.2375
A33: 1340 | B33: 0 | C33: AE | D33: 303 | E33: 302.125 | F33: 301.375 | G33: 303.375 | H33: 303.375 | I33: 303 | J33: 305.125 | L33: 304.625 | M33: 303.375 | N33: 303.25 | O33: 301.75 | P33: 302.625 | Q33: 303.375 | R33: 303.5 | S33: 301.5 | T33: 302.25 | U33: 303.75 | V33: 303 | W33: 303.625 | X33: 301.5 | Y33: =AVERAGE(D33:X33) -> 302.975
A34: 1360 | B34: 0 | C34: AE | D34: 303.75 | E34: 302.875 | F34: 303 | G34: 302 | H34: 301.375 | I34: 302 | J34: 301.875 | L34: 303.5 | M34: 301.75 | N34: 302.75 | O34: 302.25 | P34: 302.875 | Q34: 300.75 | R34: 301.875 | S34: 301 | T34: 302.25 | U34: 299.625 | V34: 302.75 | W34: 304 | X34: 302.5 | Y34: =AVERAGE(D34:X34) -> 302.2375
A35: 1380 | B35: 0 | C35: AE | D35: 303.125 | E35: 300.125 | F35: 300.75 | G35: 303.375 | H35: 300.5 | I35: 301.375 | J35: 301.5 | L35: 302.25 | M35: 303.875 | N35: 302.625 | O35: 302.25 | P35: 306.125 | Q35: 301.25 | R35: 301.5 | S35: 303 | T35: 304.125 | U35: 303.25 | V35: 303.125 | W35: 303.5 | X35: 301.375 | Y35: =AVERAGE(D35:X35) -> 302.45
... A55: 1780 | B55: 0 | C55: AE | D55: 305.875 | E55: 306.875 | F55: 307.125 | G55: 308.875 | H55: 310.75 | I55: 309 | J55: 308.75 | L55: 308.625 | M55: 306.5 | N55: 306.25 | O55: 308.875 | P55: 308.375 | Q55: 305.75 | R55: 310.75 | S55: 309.5 | T55: 310.5 | U55: 310.375 | V55: 307.5 | W55: 309.375 | X55: 307.25 | Y55: =AVERAGE(D55:X55) -> 308.34375
Y56: =AVERAGE(Y1:Y55) -> 303.4638
A61: 700 | B61: 0 | C61: WE | D61: 318.5 | E61: 317.5 | F61: 317.625 | G61: 320.375 | H61: 319.75 | I61: 318.75 | J61: 319.375 | L61: 320 | M61: 321.5 | N61: 318.375 | O61: 317.875 | P61: 320 | Q61: 320.875 | R61: 317.125 | S61: 318.875 | T61: 319.625 | U61: 317.625 | V61: 318.25 | W61: 318.875 | X61: 319.75 | Y61: =AVERAGE(D61:X61) -> 319.03125
A62: 720 | B62: 0 | C62: WE | D62: 315.625 | E62: 319.875 | F62: 316.5 | G62: 320.5 | H62: 320.375 | I62: 320 | J62: 317.625 | L62: 317.25 | M62: 317.25 | N62: 319.125 | O62: 318.25 | P62: 315.125 | Q62: 318.375 | R62: 317.625 | S62: 319.5 | T62: 315.5 | U62: 317.625 | V62: 319.125 | W62: 319.25 | X62: 316.375 | Y62: =AVERAGE(D62:X62) -> 318.04375
A63: 740 | B63: 0 | C63: WE | D63: 318.375 | E63: 317.5 | F63: 312.375 | G63: 317.125 | H63: 316 | I63: 318.375 | J63: 318.125 | L63: 317.75 | M63: 315.875 | N63: 317.125 | O63: 318.25 | P63: 319.625 | Q63: 316.5 | R63: 319.75 | S63: 316.75 | T63: 310.625 | U63: 316 | V63: 317.125 | W63: 315.375 | X63: 317.75 | Y63: =AVERAGE(D63:X63) -> 316.81875
...

Sheet WET_3
A1: 700 | B1: 0 | C1: AE | D1: 300 | E1: 299.875 | F1: 298.5 | G1: 301.25 | H1: 301.875 | I1: 299.625 | J1: 300.125 | K1: 300.75 | L1: 301.375 | M1: 301.25 | N1: 301.625 | O1: 302.25 | P1: 302.25 | Q1: 299.625 | R1: 301.625 | S1: 303 | T1: 304.625 | U1: 302.375 | V1: 302.625 | W1: 300.25 | X1: =AVERAGE(D1:W1) -> 301.24375
A2: 720 | B2: 0 | C2: AE | D2: 300 | E2: 301.625 | F2: 301 | G2: 301.25 | H2: 300.375 | I2: 300 | J2: 301.875 | K2: 300.5 | L2: 300.375 | M2: 300.25 | N2: 302.875 | O2: 299.125 | P2: 302 | Q2: 302.25 | R2: 302.125 | S2: 302.375 | T2: 301.625 | U2: 300.75 | V2: 300.125 | W2: 301.625 | X2: =AVERAGE(D2:W2) -> 301.10625
A3: 740 | B3: 0 | C3: AE | D3: 301 | E3: 300.875 | F3: 299.875 | G3: 296.75 | H3: 299.875 | I3: 301.375 | J3: 300 | K3: 301.75 | L3: 300.125 | M3: 299.75 | N3: 299.125 | O3: 299.625 | P3: 298.375 | Q3: 300.875 | R3: 299.5 | S3: 300.375 | T3: 302.25 | U3: 301.125 | V3: 300.875 | W3: 297.875 | X3: =AVERAGE(D3:W3) -> 300.06875
A4: 760 | B4: 0 | C4: AE | D4: 299.5 | E4: 300.125 | F4: 300.625 | G4: 300.75 | H4: 301.125 | I4: 301 | J4: 299.375 | K4: 299.375 | L4: 298.625 | M4: 302.25 | N4: 300.125 | O4: 299.75 | P4: 297.625 | Q4: 299.5 | R4: 298.875 | S4: 300.375 | T4: 300 | U4: 302 | V4: 299.25 | W4: 300.5 | X4: =AVERAGE(D4:W4) -> 300.0375
A5: 780 | B5: 0 | C5: AE | D5: 298.875 | E5: 299.125 | F5: 298.75 | G5: 300 | H5: 299.25 | I5: 299.5 | J5: 299.75 | K5: 298 | L5: 300.75 | M5: 298.5 | N5: 299.25 | O5: 299.375 | P5: 301.25 | Q5: 300 | R5: 299.25 | S5: 299.625 | T5: 299 | U5: 298.875 | V5: 299.25 | W5: 298.125 | X5: =AVERAGE(D5:W5) -> 299.325
A6: 800 | B6: 0 | C6: AE | D6: 297.875 | E6: 300.875 | F6: 300.375 | G6: 301.25 | H6: 298.25 | I6: 299.25 | J6: 300.625 | K6: 299.125 | L6: 300 | M6: 298.5 | N6: 298.875 | O6: 299.25 | P6: 298 | Q6: 299.875 | R6: 300.75 | S6: 299 | T6: 299.125 | U6: 300.375 | V6: 300.25 | W6: 301.125 | X6: =AVERAGE(D6:W6) -> 299.6375
A7: 820 | B7: 0 | C7: AE | D7: 301.375 | E7: 299.75 | F7: 299.625 | G7: 298 | H7: 298.25 | I7: 300.375 | J7: 296.75 | K7: 300.375 | L7: 300.125 | M7: 301 | N7: 299.875 | O7: 296.25 | P7: 299.125 | Q7: 300.125 | R7: 300 | S7: 300.125 | T7: 300.375 | U7: 299.625 | V7: 299 | W7: 298.375 | X7: =AVERAGE(D7:W7) -> 299.425
A8: 840 | B8: 0 | C8: AE | D8: 299.125 | E8: 299 | F8: 299.625 | G8: 299 | H8: 300.25 | I8: 299 | J8: 299 | K8: 298.375 | L8: 299.875 | M8: 301.125 | N8: 298.25 | O8: 298.875 | P8: 297.25 | Q8: 299.625 | R8: 299 | S8: 299 | T8: 299.875 | U8: 297.75 | V8: 300.375 | W8: 298.5 | X8: =AVERAGE(D8:W8) -> 299.14375
A9: 860 | B9: 0 | C9: AE | D9: 300.5 | E9: 299.125 | F9: 299.125 | G9: 300 | H9: 299 | I9: 298.75 | J9: 299.625 | K9: 300 | L9: 298.5 | M9: 298.625 | N9: 297.75 | O9: 299.25 | P9: 301.875 | Q9: 301.625 | R9: 299.125 | S9: 299.25 | T9: 298.875 | U9: 299.25 | V9: 297 | W9: 299.625 | X9: =AVERAGE(D9:W9) -> 299.34375
A10: 880 | B10: 0 | C10: AE | D10: 298.75 | E10: 298.875 | F10: 296.875 | G10: 299.5 | H10: 298.75 | I10: 297.375 | J10: 297.875 | K10: 299.5 | L10: 297.75 | M10: 302.875 | N10: 300.75 | O10: 301.125 | P10: 299.875 | Q10: 298.875 | R10: 297.125 | S10: 299.125 | T10: 299.125 | U10: 299.375 | V10: 300.25 | W10: 297.125 | X10: =AVERAGE(D10:W10) -> 299.04375
A11: 900 | B11: 0 | C11: AE | D11: 299.125 | E11: 298.5 | F11: 297.375 | G11: 298.75 | H11: 298 | I11: 299 | J11: 298.25 | K11: 300.5 | L11: 299.875 | M11: 298.375 | N11: 298.75 | O11: 299.375 | P11: 298.25 | Q11: 300.625 | R11: 299.75 | S11: 297.125 | T11: 300.125 | U11: 299.75 | V11: 296.5 | W11: 297.75 | X11: =AVERAGE(D11:W11) -> 298.7875
A12: 920 | B12: 0 | C12: AE | D12: 298.25 | E12: 297.625 | F12: 299.375 | G12: 299.25 | H12: 297.25 | I12: 299.125 | J12: 300.125 | K12: 298.75 | L12: 300 | M12: 295.75 | N12: 298.25 | O12: 298 | P12: 296.5 | Q12: 296.875 | R12: 299.625 | S12: 298.625 | T12: 299.75 | U12: 296.875 | V12: 297.5 | W12: 297.75 | X12: =AVERAGE(D12:W12) -> 298.2625
... A31: 1300 | B31: 0 | C31: AE | D31: 294.875 | E31: 296.5 | F31: 295.625 | G31: 296.125 | H31: 297.5 | I31: 295 | J31: 296.875 | K31: 295.625 | L31: 297 | M31: 298.125 | N31: 295.125 | O31: 292.625 | P31: 295.375 | Q31: 295.875 | R31: 297.25 | S31: 295.75 | T31: 297.375 | U31: 297.625 | V31: 296.125 | W31: 296.125 | X31: =AVERAGE(D31:W31) -> 296.125
X32: =AVERAGE(X1:X31) -> 298.07944
A37: 700 | B37: 0 | C37: WE | D37: 308.5 | E37: 308.875 | F37: 309.375 | G37: 310.5 | H37: 310.375 | I37: 309 | J37: 309.75 | K37: 311.875 | L37: 309.5 | M37: 311.375 | N37: 314.125 | O37: 311 | P37: 311.375 | Q37: 310.875 | R37: 311.25 | S37: 310.5 | T37: 314.5 | U37: 313.25 | V37: 312.25 | W37: 311.125 | X37: =AVERAGE(D37:W37) -> 310.96875
A38: 720 | B38: 0 | C38: WE | D38: 311.125 | E38: 310.25 | F38: 311.75 | G38: 311.5 | H38: 308.875 | I38: 310.5 | J38: 308.75 | K38: 308.5 | L38: 310.875 | M38: 310.125 | N38: 312 | O38: 309.125 | P38: 312.625 | Q38: 310.625 | R38: 310.25 | S38: 309 | T38: 311 | U38: 310.875 | V38: 310.625 | W38: 310.75 | X38: =AVERAGE(D38:W38) -> 310.45625
A39: 740 | B39: 0 | C39: WE | D39: 310.5 | E39: 309 | F39: 309.25 | G39: 308.375 | H39: 310.25 | I39: 311.375 | J39: 309.25 | K39: 310.625 | L39: 312.5 | M39: 312.25 | N39: 309.375 | O39: 309.5 | P39: 308 | Q39: 307.625 | R39: 309 | S39: 311.5 | T39: 313 | U39: 310.375 | V39: 311.5 | W39: 308.625 | X39: =AVERAGE(D39:W39) -> 310.09375
A40: 760 | B40: 0 | C40: WE | D40: 308.75 | E40: 309.375 | F40: 308.75 | G40: 310 | H40: 308.125 | I40: 310 | J40: 310.25 | K40: 310.375 | L40: 310.75 | M40: 310.5 | N40: 309.375 | O40: 307.125 | P40: 306.875 | Q40: 309.5 | R40: 309.375 | S40: 308.5 | T40: 311 | U40: 311.625 | V40: 307.875 | W40: 308.875 | X40: =AVERAGE(D40:W40) -> 309.35
A41: 780 | B41: 0 | C41: WE | D41: 307.375 | E41: 309.625 | F41: 308.25 | G41: 310 | H41: 307.875 | I41: 307.875 | J41: 307.25 | K41: 308.25 | L41: 308.625 | M41: 309.375 | N41: 310.5 | O41: 308.5 | P41: 311.25 | Q41: 308.875 | R41: 307.25 | S41: 309.25 | T41: 309 | U41: 310.5 | V41: 307.875 | W41: 309.5 | X41: =AVERAGE(D41:W41) -> 308.85
A42: 800 | B42: 0 | C42: WE | D42: 305.625 | E42: 309 | F42: 309.125 | G42: 307.5 | H42: 307.25 | I42: 308.875 | J42: 311.375 | K42: 309.375 | L42: 309 | M42: 309.875 | N42: 309.75 | O42: 306.5 | P42: 307.375 | Q42: 306.875 | R42: 308 | S42: 310.875 | T42: 308.25 | U42: 310.375 | V42: 308.75 | W42: 309.625 | X42: =AVERAGE(D42:W42) -> 308.66875
A43: 820 | B43: 0 | C43: WE | D43: 308.625 | E43: 308.125 | F43: 307 | G43: 306.375 | H43: 308.75 | I43: 309.875 | J43: 307.25 | K43: 309.625 | L43: 309.5 | M43: 310.5 | N43: 309.875 | O43: 307.25 | P43: 307.875 | Q43: 309.5 | R43: 308.5 | S43: 308.625 | T43: 308.75 | U43: 309 | V43: 308 | W43: 307 | X43: =AVERAGE(D43:W43) -> 308.5
A44: 840 | B44: 0 | C44: WE | D44: 306.75 | E44: 307.5 | F44: 307.5 | G44: 309 | H44: 307.375 | I44: 307.5 | J44: 308.75 | K44: 306.375 | L44: 307.25 | M44: 308.75 | N44: 304.625 | O44: 308.125 | P44: 308.875 | Q44: 306.25 | R44: 307.875 | S44: 307.875 | T44: 307.75 | U44: 305.375 | V44: 308.125 | W44: 306 | X44: =AVERAGE(D44:W44) -> 307.38125
A45: 860 | B45: 0 | C45: WE | D45: 307.5 | E45: 307.75 | F45: 308.5 | G45: 308.25 | H45: 307 | I45: 306.875 | J45: 307.625 | K45: 311.5 | L45: 308.25 | M45: 307.125 | N45: 304.875 | O45: 308.75 | P45: 309 | Q45: 309.375 | R45: 308.125 | S45: 307.625 | T45: 306.375 | U45: 307 | V45: 307.5 | W45: 308.25 | X45: =AVERAGE(D45:W45) -> 307.8625
A46: 880 | B46: 0 | C46: WE | D46: 306.5 | E46: 306.625 | F46: 306.5 | G46: 308.375 | H46: 306.625 | I46: 306.125 | J46: 305.625 | K46: 307.5 | L46: 307.875 | M46: 311 | N46: 308.875 | O46: 311.125 | P46: 307.125 | Q46: 306.875 | R46: 306 | S46: 306.25 | T46: 309.375 | U46: 308.75 | V46: 305.375 | W46: 306.25 | X46: =AVERAGE(D46:W46) -> 307.4375
A47: 900 | B47: 0 | C47: WE | D47: 307.375 | E47: 306.625 | F47: 304.75 | G47: 308.125 | H47: 305.875 | I47: 306.625 | J47: 306.375 | K47: 306 | L47: 307.875 | M47: 308.25 | N47: 307.25 | O47: 307.375 | P47: 306 | Q47: 307.75 | R47: 308.75 | S47: 306.125 | T47: 308.875 | U47: 306.25 | V47: 304.875 | W47: 308.25 | X47: =AVERAGE(D47:W47) -> 306.96875
A48: 920 | B48: 0 | C48: WE | D48: 307.125 | E48: 307.125 | F48: 307 | G48: 307.625 | H48: 306 | I48: 307.625 | J48: 308.625 | K48: 307.125 | L48: 308.5 | M48: 308.125 | N48: 306.125 | O48: 304.375 | P48: 306 | Q48: 306.625 | R48: 307.875 | S48: 307.625 | T48: 307.375 | U48: 302.875 | V48: 304.75 | W48: 305.375 | X48: =AVERAGE(D48:W48) -> 306.69375
... A67: 1300 | B67: 0 | C67: WE | D67: 303.875 | E67: 304.75 | F67: 302.625 | G67: 304.625 | H67: 304.25 | I67: 302.625 | J67: 302 | K67: 302.75 | L67: 303.5 | M67: 304 | N67: 302.25 | O67: 301.625 | P67: 304.875 | Q67: 302.125 | R67: 302.75 | S67: 303.125 | T67: 302.625 | U67: 305.125 | V67: 304.5 | W67: 301.625 | X67: =AVERAGE(D67:W67) -> 303.28125
X68: =AVERAGE(X37:X67) -> 306.08992
A74: 700 | B74: 1 | C74: AE | D74: 302.25 | E74: 301.875 | F74: 300 | G74: 301 | H74: 300.625 | I74: 300.375 | J74: 302.75 | K74: 300.375 | L74: 300.625 | M74: 303 | N74: 299 | O74: 300.125 | P74: 300.5 | Q74: 300.125 | R74: 298.75 | S74: 297.625 | T74: 299.125 | U74: 299.75 | V74: 300.875 | W74: 298.375 | X74: =AVERAGE(D74:W74) -> 300.35625
A75: 720 | B75: 1 | C75: AE | D75: 299.625 | E75: 298.5 | F75: 300.5 | G75: 297.75 | H75: 300.875 | I75: 301.375 | J75: 301.25 | K75: 299.5 | L75: 299.375 | M75: 299.625 | N75: 299 | O75: 299.125 | P75: 300 | Q75: 300.75 | R75: 299.5 | S75: 299.875 | T75: 298.875 | U75: 300.125 | V75: 301.625 | W75: 302.75 | X75: =AVERAGE(D75:W75) -> 300
A76: 740 | B76: 1 | C76: AE | D76: 297.625 | E76: 300 | F76: 298.25 | G76: 298.875 | H76: 299.625 | I76: 299.875 | J76: 299.5 | K76: 300 | L76: 300.625 | M76: 299 | N76: 298.875 | O76: 297.75 | P76: 301.75 | Q76: 297.75 | R76: 298.75 | S76: 299.25 | T76: 300.25 | U76: 299.125 | V76: 300.25 | W76: 299 | X76: =AVERAGE(D76:W76) -> 299.30625
A77: 760 | B77: 1 | C77: AE | D77: 298.875 | E77: 298.375 | F77: 297.75 | G77: 299.5 | H77: 300 | I77: 300 | J77: 300 | K77: 298.75 | L77: 299.5 | M77: 298 | N77: 299.25 | O77: 301 | P77: 297.75 | Q77: 298.25 | R77: 299.75 | S77: 301.375 | T77: 300.25 | U77: 297.375 | V77: 297.375 | W77: 298.75 | X77: =AVERAGE(D77:W77) -> 299.09375
A78: 780 | B78: 1 | C78: AE | D78: 300.125 | E78: 297.625 | F78: 297.75 | G78: 298 | H78: 298.375 | I78: 300.375 | J78: 297.5 | K78: 298.5 | L78: 300 | M78: 301.375 | N78: 299.375 | O78: 298.625 | P78: 298.625 | Q78: 299.75 | R78: 298.875 | S78: 298.375 | T78: 297.375 | U78: 300.375 | V78: 298.625 | W78: 298 | X78: =AVERAGE(D78:W78) -> 298.88125
A79: 800 | B79: 1 | C79: AE | D79: 297 | E79: 297.625 | F79: 300.375 | G79: 298.75 | H79: 300 | I79: 299.125 | J79: 298.625 | K79: 298.875 | L79: 296.75 | M79: 299.75 | N79: 300.875 | O79: 299.375 | P79: 299.625 | Q79: 296.25 | R79: 299.25 | S79: 297.375 | T79: 298 | U79: 296.375 | V79: 298.875 | W79: 298 | X79: =AVERAGE(D79:W79) -> 298.54375
A80: 820 | B80: 1 | C80: AE | D80: 299.375 | E80: 298 | F80: 299.125 | G80: 300.375 | H80: 297.5 | I80: 298 | J80: 298.25 | K80: 297.75 | L80: 298.375 | M80: 299.75 | N80: 300.375 | O80: 299.625 | P80: 299.25 | Q80: 298.375 | R80: 297.5 | S80: 299.375 | T80: 298.625 | U80: 301.125 | V80: 300.125 | W80: 296.125 | X80: =AVERAGE(D80:W80) -> 298.85
A81: 840 | B81: 1 | C81: AE | D81: 296.625 | E81: 295.25 | F81: 297.375 | G81: 299.625 | H81: 297.875 | I81: 298.75 | J81: 298.375 | K81: 298.375 | L81: 300 | M81: 297.625 | N81: 298.25 | O81: 297.25 | P81: 298.625 | Q81: 296.875 | R81: 299 | S81: 297 | T81: 297.25 | U81: 299.5 | V81: 299.875 | W81: 298.875 | X81: =AVERAGE(D81:W81) -> 298.11875
A82: 860 | B82: 1 | C82: AE | D82: 297.375 | E82: 299.25 | F82: 296.625 | G82: 295.375 | H82: 298.375 | I82: 297.25 | J82: 300 | K82: 297.75 | L82: 298 | M82: 298.125 | N82: 297.25 | O82: 299.25 | P82: 297.25 | Q82: 299.125 | R82: 299 | S82: 296.5 | T82: 298.25 | U82: 296.875 | V82: 297 | W82: 299.125 | X82: =AVERAGE(D82:W82) -> 297.8875
A83: 880 | B83: 1 | C83: AE | D83: 298.125 | E83: 297.875 | F83: 297.875 | G83: 298.875 | H83: 297.75 | I83: 296.125 | J83: 300.125 | K83: 299.125 | L83: 299 | M83: 297.625 | N83: 297.25 | O83: 297.625 | P83: 298.5 | Q83: 298.375 | R83: 296.75 | S83: 297.5 | T83: 299.125 | U83: 296.625 | V83: 299.125 | W83: 297.875 | X83: =AVERAGE(D83:W83) -> 298.0625
A84: 900 | B84: 1 | C84: AE | D84: 297 | E84: 297.125 | F84: 299 | G84: 297.875 | H84: 297.5 | I84: 298.25 | J84: 299 | K84: 296.75 | L84: 297.375 | M84: 297.75 | N84: 297.375 | O84: 298.125 | P84: 297.75 | Q84: 297.75 | R84: 297.75 | S84: 297.75 | T84: 299.25 | U84: 300 | V84: 298.625 | W84: 297.125 | X84: =AVERAGE(D84:W84) -> 297.95625
A85: 920 | B85: 1 | C85: AE | D85: 297.375 | E85: 298.875 | F85: 299 | G85: 296.625 | H85: 297.5 | I85: 296.75 | J85: 298.5 | K85: 298.875 | L85: 297.625 | M85: 295.875 | N85: 298 | O85: 296.125 | P85: 298.875 | Q85: 297.875 | R85: 296.75 | S85: 299 | T85: 295.75 | U85: 295.875 | V85: 296.625 | W85: 297.875 | X85: =AVERAGE(D85:W85) -> 297.4875
...

Sheet WET_2
A1: 20 | B1: 0 | C1: AE | D1: 363.125 | E1: 364.5 | F1: 360.5 | G1: 355.875 | H1: 364.125 | I1: 362.5 | J1: 363.5 | K1: 359.875 | L1: 365.625 | M1: 365.875 | N1: 362.125 | O1: 352.5 | P1: 365.25 | Q1: 362.875 | R1: 362.75 | S1: 362.25 | T1: 361.625 | U1: 360 | V1: 364.25 | W1: 361.125 | X1: =AVERAGE(D1:W1) -> 362.0125
A2: 40 | B2: 0 | C2: AE | D2: 344.375 | E2: 345 | F2: 345.875 | G2: 344.375 | H2: 342.875 | I2: 342.875 | J2: 342.75 | K2: 343.5 | L2: 341.875 | M2: 343 | N2: 344.875 | O2: 344.5 | P2: 346.75 | Q2: 345.125 | R2: 344.625 | S2: 348 | T2: 345.125 | U2: 345.875 | V2: 343.875 | W2: 345 | X2: =AVERAGE(D2:W2) -> 344.5125
A3: 60 | B3: 0 | C3: AE | D3: 336.125 | E3: 336.375 | F3: 337.125 | G3: 337.25 | H3: 335.875 | I3: 335.125 | J3: 335.25 | K3: 335.625 | L3: 336.625 | M3: 336.25 | N3: 333.875 | O3: 336.25 | P3: 334.75 | Q3: 335.875 | R3: 337 | S3: 336.625 | T3: 336.25 | U3: 336.25 | V3: 337.375 | W3: 335 | X3: =AVERAGE(D3:W3) -> 336.04375
A4: 80 | B4: 0 | C4: AE | D4: 328.875 | E4: 331.75 | F4: 331.25 | G4: 330.25 | H4: 329 | I4: 331.5 | J4: 331.375 | K4: 332.125 | L4: 331.75 | M4: 331 | N4: 330.875 | O4: 334.625 | P4: 331.125 | Q4: 331 | R4: 332.125 | S4: 329.75 | T4: 328.875 | U4: 329.5 | V4: 331 | W4: 331.125 | X4: =AVERAGE(D4:W4) -> 330.94375
A5: 100 | B5: 0 | C5: AE | D5: 329.375 | E5: 329.5 | F5: 329.125 | G5: 326.375 | H5: 327.5 | I5: 328.25 | J5: 327.5 | K5: 327.625 | L5: 327 | M5: 326.125 | N5: 327.125 | O5: 328.5 | P5: 326.625 | Q5: 327.5 | R5: 326.75 | S5: 326.25 | T5: 327.75 | U5: 329.125 | V5: 326.75 | W5: 328 | X5: =AVERAGE(D5:W5) -> 327.6375
A6: 120 | B6: 0 | C6: AE | D6: 326 | E6: 326.375 | F6: 326.75 | G6: 325.75 | H6: 326.5 | I6: 323.5 | J6: 324 | K6: 326.5 | L6: 325.625 | M6: 324.75 | N6: 325.25 | O6: 324 | P6: 326.875 | Q6: 325.625 | R6: 325.25 | S6: 324.625 | T6: 323 | U6: 322.5 | V6: 325.625 | W6: 322.125 | X6: =AVERAGE(D6:W6) -> 325.03125
A7: 140 | B7: 0 | C7: AE | D7: 326.875 | E7: 324.375 | F7: 324.75 | G7: 325.25 | H7: 325.125 | I7: 324.375 | J7: 324.25 | K7: 324.5 | L7: 322.875 | M7: 326.875 | N7: 325.5 | O7: 325.375 | P7: 323.5 | Q7: 324.875 | R7: 324.75 | S7: 324.75 | T7: 325 | U7: 325.375 | V7: 322.125 | W7: 324 | X7: =AVERAGE(D7:W7) -> 324.725
A8: 160 | B8: 0 | C8: AE | D8: 323.5 | E8: 321.625 | F8: 321.625 | G8: 322.125 | H8: 323.375 | I8: 324.375 | J8: 322.125 | K8: 323.75 | L8: 323.875 | M8: 322.75 | N8: 324.75 | O8: 325.125 | P8: 323.75 | Q8: 323.125 | R8: 323 | S8: 323 | T8: 323.125 | U8: 322.25 | V8: 320.75 | W8: 324.25 | X8: =AVERAGE(D8:W8) -> 323.1125
A9: 180 | B9: 0 | C9: AE | D9: 323.25 | E9: 321.625 | F9: 319.75 | G9: 321.125 | H9: 323.125 | I9: 321.125 | J9: 320.125 | K9: 321.875 | L9: 323.5 | M9: 321.125 | N9: 319.625 | O9: 321.125 | P9: 323 | Q9: 321 | R9: 322.375 | S9: 323.875 | T9: 322.875 | U9: 320.125 | V9: 323.75 | W9: 320.875 | X9: =AVERAGE(D9:W9) -> 321.7625
A10: 200 | B10: 0 | C10: AE | D10: 318.875 | E10: 320.625 | F10: 319.125 | G10: 322.125 | H10: 322.625 | I10: 322.25 | J10: 323 | K10: 320.375 | L10: 319.375 | M10: 322.625 | N10: 320.25 | O10: 319.25 | P10: 319.625 | Q10: 320 | R10: 319.75 | S10: 320 | T10: 320.875 | U10: 318.875 | V10: 321.125 | W10: 320.375 | X10: =AVERAGE(D10:W10) -> 320.55625
A11: 220 | B11: 0 | C11: AE | D11: 318.25 | E11: 317.75 | F11: 318 | G11: 320 | H11: 318.75 | I11: 317.75 | J11: 317.875 | K11: 316.625 | L11: 318.625 | M11: 318.875 | N11: 320.375 | O11: 321.25 | P11: 319.875 | Q11: 320.125 | R11: 322.375 | S11: 319.125 | T11: 320 | U11: 321.375 | V11: 319.75 | W11: 321.25 | X11: =AVERAGE(D11:W11) -> 319.4
A12: 240 | B12: 0 | C12: AE | D12: 317.375 | E12: 316.125 | F12: 318.75 | G12: 319.5 | H12: 318.5 | I12: 318.625 | J12: 316.875 | K12: 317.25 | L12: 317 | M12: 316.25 | N12: 315.75 | O12: 315.75 | P12: 318.375 | Q12: 316.625 | R12: 317.5 | S12: 318.25 | T12: 318.625 | U12: 317.25 | V12: 318 | W12: 317.25 | X12: =AVERAGE(D12:W12) -> 317.48125
... A35: 700 | B35: 0 | C35: AE | D35: 304.625 | E35: 303.75 | F35: 302.875 | G35: 302.875 | H35: 304.375 | I35: 302 | J35: 303.625 | K35: 303.5 | L35: 305 | M35: 302.375 | N35: 302 | O35: 304.875 | P35: 304.625 | Q35: 303.375 | R35: 304.625 | S35: 305 | T35: 303.25 | U35: 302.625 | V35: 302.875 | W35: 302 | X35: =AVERAGE(D35:W35) -> 303.5125
X36: =AVERAGE(X17:X35) -> 306.34145
A41: 20 | B41: 0 | C41: WE | D41: 412.375 | E41: 416.375 | F41: 413.375 | G41: 406.125 | H41: 415.375 | I41: 411.75 | J41: 414.625 | K41: 406.625 | L41: 414.375 | M41: 415.125 | N41: 412.75 | O41: 410.625 | P41: 415.625 | Q41: 416.875 | R41: 410.5 | S41: 415.375 | T41: 412.125 | U41: 412.125 | V41: 414.25 | W41: 412.75 | X41: =AVERAGE(D41:W41) -> 412.95625
A42: 40 | B42: 0 | C42: WE | D42: 385 | E42: 387.625 | F42: 385.25 | G42: 384.75 | H42: 384.875 | I42: 381 | J42: 384.375 | K42: 381.75 | L42: 382.125 | M42: 383.625 | N42: 383.5 | O42: 385.5 | P42: 386.5 | Q42: 386.25 | R42: 387.25 | S42: 388.375 | T42: 386.75 | U42: 385.875 | V42: 384 | W42: 386.625 | X42: =AVERAGE(D42:W42) -> 385.05
A43: 60 | B43: 0 | C43: WE | D43: 371.125 | E43: 372.625 | F43: 373.625 | G43: 374.625 | H43: 372.875 | I43: 370.875 | J43: 372.25 | K43: 371.875 | L43: 372.625 | M43: 373.375 | N43: 371.25 | O43: 370.875 | P43: 373.875 | Q43: 372 | R43: 371.25 | S43: 371.375 | T43: 373.125 | U43: 371.25 | V43: 373.25 | W43: 371.875 | X43: =AVERAGE(D43:W43) -> 372.3
A44: 80 | B44: 0 | C44: WE | D44: 363.125 | E44: 362.625 | F44: 363.875 | G44: 361.875 | H44: 362.5 | I44: 365.125 | J44: 365.125 | K44: 364.625 | L44: 364.125 | M44: 364.875 | N44: 366.25 | O44: 365.125 | P44: 365.5 | Q44: 363.875 | R44: 365.25 | S44: 363.375 | T44: 361.5 | U44: 361.375 | V44: 364.75 | W44: 364.25 | X44: =AVERAGE(D44:W44) -> 363.95625
A45: 100 | B45: 0 | C45: WE | D45: 359 | E45: 358.5 | F45: 358.25 | G45: 358.125 | H45: 359.5 | I45: 360.5 | J45: 358 | K45: 359.5 | L45: 357.625 | M45: 357.5 | N45: 358.5 | O45: 359.125 | P45: 356.875 | Q45: 357.375 | R45: 357.375 | S45: 357.75 | T45: 355.125 | U45: 359.25 | V45: 357 | W45: 358.25 | X45: =AVERAGE(D45:W45) -> 358.15625
A46: 120 | B46: 0 | C46: WE | D46: 355.375 | E46: 356.125 | F46: 355.875 | G46: 352.75 | H46: 353.625 | I46: 352.625 | J46: 355.625 | K46: 354.5 | L46: 354.75 | M46: 354.75 | N46: 353.625 | O46: 353.875 | P46: 356.625 | Q46: 353.125 | R46: 355.125 | S46: 355.125 | T46: 353.5 | U46: 352.75 | V46: 354.25 | W46: 351.625 | X46: =AVERAGE(D46:W46) -> 354.28125
